<?xml version="1.0"?>
<!--
  Robot: my_robot
  Generated by: LinkForge v1.1.0
  https://github.com/arounamounchili/linkforge
  Date: 2026-01-23 12:39:54
-->
<robot name="my_robot">
  <!-- Links -->
  <link name="link1">
    <visual>
      <geometry>
        <mesh filename="meshes\link1_visual.stl" />
      </geometry>
    </visual>
    <collision>
      <origin xyz="-0.208339 0.066752 0.052332" rpy="-0.050738 0 0" />
      <geometry>
        <mesh filename="meshes\link1_collision.stl" />
      </geometry>
    </collision>
    <inertial>
      <mass value="0.1" />
      <inertia ixx="0.00154" ixy="0" ixz="-0.000024" iyy="0.00269" iyz="0" izz="0.002106" />
    </inertial>
  </link>
  <link name="link2">
    <visual>
      <geometry>
        <mesh filename="meshes\link2_visual.stl" />
      </geometry>
    </visual>
    <collision>
      <origin xyz="-0.207332 0.003731 0.980145" rpy="-0.050738 0 0" />
      <geometry>
        <mesh filename="meshes\link2_collision.stl" />
      </geometry>
    </collision>
    <inertial>
      <mass value="0.1" />
      <inertia ixx="0.003707" ixy="0" ixz="0.000017" iyy="0.003221" iyz="-0.000026" izz="0.001986" />
    </inertial>
  </link>
  <link name="link3">
    <visual>
      <geometry>
        <mesh filename="meshes\link3_visual.stl" />
      </geometry>
    </visual>
    <collision>
      <origin xyz="-0.121278 0.2894 0.747684" rpy="-0.050738 0 0" />
      <geometry>
        <mesh filename="meshes\link3_collision.stl" />
      </geometry>
    </collision>
    <inertial>
      <mass value="0.1" />
      <inertia ixx="0.019626" ixy="0.000121" ixz="-0.00203" iyy="0.019931" iyz="0.000216" izz="0.003385" />
    </inertial>
  </link>
  <link name="link4">
    <visual>
      <geometry>
        <mesh filename="meshes\link4_visual.stl" />
      </geometry>
    </visual>
    <collision>
      <origin xyz="2.292761 -0.454141 2.208923" rpy="-0.050738 0 0" />
      <geometry>
        <mesh filename="meshes\link4_collision.stl" />
      </geometry>
    </collision>
    <inertial>
      <mass value="0.1" />
      <inertia ixx="0.002197" ixy="0.000115" ixz="-0.000047" iyy="0.016715" iyz="0" izz="0.017499" />
    </inertial>
  </link>
  <link name="link5">
    <visual>
      <geometry>
        <mesh filename="meshes\link5_visual.stl" />
      </geometry>
    </visual>
    <collision>
      <origin xyz="1.520565 0.20001 2.06356" rpy="-0.050738 0 0" />
      <geometry>
        <mesh filename="meshes\link5_collision.stl" />
      </geometry>
    </collision>
    <inertial>
      <mass value="0.1" />
      <inertia ixx="0.015384" ixy="-0.000151" ixz="0.000384" iyy="0.00856" iyz="0.000017" izz="0.019202" />
    </inertial>
  </link>
  <link name="gripper_right_palm">
    <visual>
      <geometry>
        <mesh filename="meshes\gripper_right_palm_visual.stl" />
      </geometry>
    </visual>
    <collision>
      <origin xyz="2.469342 -0.40456 2.132662" rpy="0 0 0" />
      <geometry>
        <mesh filename="meshes\gripper_right_palm_collision.stl" />
      </geometry>
    </collision>
    <inertial>
      <mass value="0.1" />
      <inertia ixx="0.001547" ixy="-0.000338" ixz="0.000178" iyy="0.004075" iyz="0.000019" izz="0.003106" />
    </inertial>
  </link>
  <link name="gripper_left_palm">
    <visual>
      <geometry>
        <mesh filename="meshes\gripper_left_palm_visual.stl" />
      </geometry>
    </visual>
    <collision>
      <origin xyz="2.259184 0.803103 1.962756" rpy="0.002593 0 0" />
      <geometry>
        <mesh filename="meshes\gripper_left_palm_collision.stl" />
      </geometry>
    </collision>
    <inertial>
      <mass value="0.1" />
      <inertia ixx="0.001547" ixy="0.000338" ixz="-0.000178" iyy="0.004075" iyz="0.000019" izz="0.003106" />
    </inertial>
  </link>
  <!-- Joints -->
  <joint name="link2_joint" type="revolute">
    <parent link="link1" />
    <child link="link2" />
    <axis xyz="0 0 1" />
    <limit effort="5" velocity="1" lower="-3.141593" upper="3.141593" />
  </joint>
  <joint name="link3_joint" type="revolute">
    <parent link="link2" />
    <child link="link3" />
    <axis xyz="0 1 0" />
    <limit effort="5" velocity="1" lower="-3.141593" upper="3.141593" />
  </joint>
  <joint name="link4_joint" type="revolute">
    <parent link="link3" />
    <child link="link4" />
    <axis xyz="0 1 0" />
    <limit effort="5" velocity="1" lower="-3.141593" upper="3.141593" />
  </joint>
  <joint name="link5_joint" type="revolute">
    <parent link="link4" />
    <child link="link5" />
    <axis xyz="0 0 1" />
    <limit effort="5" velocity="1" lower="-3.141593" upper="3.141593" />
  </joint>
  <joint name="gripper_right_palm_joint" type="prismatic">
    <parent link="link5" />
    <child link="gripper_right_palm" />
    <axis xyz="0 1 0" />
    <limit effort="4" velocity="1" lower="-0.005" upper="0.004" />
  </joint>
  <joint name="gripper_left_palm_joint" type="prismatic">
    <parent link="link5" />
    <child link="gripper_left_palm" />
    <axis xyz="0 1 0" />
    <limit effort="4" velocity="1" lower="-0.005" upper="0.004" />
    <mimic joint="gripper_right_palm_joint" />
  </joint>
</robot>